Workbook
Name Slicer_City: #N/A
Name Slicer_Manager: #N/A
Name Slicer_Payment_Method: #N/A
Name Slicer_Product: #N/A

Sheet Raw
B2: Order ID | C2: Date | D2: Product | E2: Purchase Type | F2: Payment Method | G2: Manager | H2: City | I2: Price | J2: Quantity | K2: Total revenue
B3: 10452 | C3: 44872 | D3: Fries | E3: Online | F3: Gift Card | G3: Tom Jackson | H3: London | I3: 3.49 | J3: 574 | K3: =PRODUCT(I3:J3) -> 2003.26
B4: 10453 | C4: 44872 | D4: Beverages | E4: Online | F4: Gift Card | G4: Pablo Perez | H4: Madrid | I4: 2.95 | J4: 746 | K4: =PRODUCT(I4:J4) -> 2200.7
B5: 10454 | C5: 44872 | D5: Sides & Other | E5: In-store | F5: Gift Card | G5: Joao Silva | H5: Lisbon | I5: 4.99 | J5: 201 | K5: =PRODUCT(I5:J5) -> 1002.99
B6: 10455 | C6: 44873 | D6: Burgers | E6: In-store | F6: Credit Card | G6: Walter Muller | H6: Berlin | I6: 12.99 | J6: 570 | K6: =PRODUCT(I6:J6) -> 7404.3
B7: 10456 | C7: 44873 | D7: Chicken Sandwiches | E7: In-store | F7: Credit Card | G7: Walter Muller | H7: Berlin | I7: 9.95 | J7: 202 | K7: =PRODUCT(I7:J7) -> 2009.9
B8: 10457 | C8: 44873 | D8: Fries | E8: In-store | F8: Credit Card | G8: Remy Monet | H8: Paris | I8: 3.49 | J8: 574 | K8: =PRODUCT(I8:J8) -> 2003.26
B9: 10459 | C9: 44873 | D9: Sides & Other | E9: In-store | F9: Credit Card | G9: Walter Muller | H9: Berlin | I9: 4.99 | J9: 201 | K9: =PRODUCT(I9:J9) -> 1002.99
B10: 10460 | C10: 44874 | D10: Burgers | E10: In-store | F10: Credit Card | G10: Remy Monet | H10: Paris | I10: 12.99 | J10: 555 | K10: =PRODUCT(I10:J10) -> 7209.45
B11: 10461 | C11: 44874 | D11: Chicken Sandwiches | E11: In-store | F11: Credit Card | G11: Remy Monet | H11: Paris | I11: 9.95 | J11: 202 | K11: =PRODUCT(I11:J11) -> 2009.9
B12: 10462 | C12: 44874 | D12: Fries | E12: In-store | F12: Credit Card | G12: Remy Monet | H12: Paris | I12: 3.49 | J12: 574 | K12: =PRODUCT(I12:J12) -> 2003.26
B13: 10463 | C13: 44874 | D13: Beverages | E13: In-store | F13: Credit Card | G13: Remy Monet | H13: Paris | I13: 2.95 | J13: 678 | K13: =PRODUCT(I13:J13) -> 2000.1
B14: 10464 | C14: 44874 | D14: Sides & Other | E14: In-store | F14: Credit Card | G14: Remy Monet | H14: Paris | I14: 4.99 | J14: 201 | K14: =PRODUCT(I14:J14) -> 1002.99
... B239: 10693 | C239: 44920 | D239: Beverages | E239: In-store | F239: Cash | G239: Walter Muller | H239: Berlin | I239: 2.95 | J239: 678 | K239: =PRODUCT(I239:J239) -> 2000.1
B240: 10694 | C240: 44920 | D240: Sides & Other | E240: In-store | F240: Cash | G240: Walter Muller | H240: Berlin | I240: 4.99 | J240: 201 | K240: =PRODUCT(I240:J240) -> 1002.99 | O240: Column1 | R240: Column1
B241: 10695 | C241: 44921 | D241: Burgers | E241: In-store | F241: Cash | G241: Walter Muller | H241: Berlin | I241: 12.99 | J241: 693 | K241: =PRODUCT(I241:J241) -> 9002.07
B242: 10696 | C242: 44921 | D242: Chicken Sandwiches | E242: In-store | F242: Cash | G242: Walter Muller | H242: Berlin | I242: 9.95 | J242: 282 | K242: =PRODUCT(I242:J242) -> 2805.9 | O242: Mean | P242: 3160.0589 | R242: Mean | S242: 461.24125
B243: 10697 | C243: 44921 | D243: Fries | E243: In-store | F243: Cash | G243: Walter Muller | H243: Berlin | I243: 3.49 | J243: 631 | K243: =PRODUCT(I243:J243) -> 2202.19 | O243: Standard Error | P243: 174.18697 | R243: Standard Error | S243: 13.380974
B244: 10698 | C244: 44921 | D244: Beverages | E244: In-store | F244: Cash | G244: Walter Muller | H244: Berlin | I244: 2.95 | J244: 678 | K244: =PRODUCT(I244:J244) -> 2000.1 | O244: Median | P244: 2200.7 | R244: Median | S244: 539
B245: 10699 | C245: 44921 | D245: Sides & Other | E245: In-store | F245: Cash | G245: Walter Muller | H245: Berlin | I245: 4.99 | J245: 201 | K245: =PRODUCT(I245:J245) -> 1002.99 | O245: Mode | P245: 1002.99 | R245: Mode | S245: 201
B246: 10700 | C246: 44922 | D246: Burgers | E246: In-store | F246: Cash | G246: Walter Muller | H246: Berlin | I246: 12.99 | J246: 693 | K246: =PRODUCT(I246:J246) -> 9002.07 | O246: Standard Deviation | P246: 2792.4296 | R246: Standard Deviation | S246: 214.51334
B247: 10701 | C247: 44922 | D247: Chicken Sandwiches | E247: In-store | F247: Cash | G247: Walter Muller | H247: Berlin | I247: 9.95 | J247: 282 | K247: =PRODUCT(I247:J247) -> 2805.9 | O247: Sample Variance | P247: 7797663.1 | R247: Sample Variance | S247: 46015.973
B248: 10702 | C248: 44922 | D248: Fries | E248: In-store | F248: Cash | G248: Walter Muller | H248: Berlin | I248: 3.49 | J248: 631 | K248: =PRODUCT(I248:J248) -> 2202.19 | O248: Kurtosis | P248: 10.622385 | R248: Kurtosis | S248: -1.7242037
B249: 10703 | C249: 44922 | D249: Beverages | E249: In-store | F249: Gift Card | G249: Walter Muller | H249: Berlin | I249: 2.95 | J249: 678 | K249: =PRODUCT(I249:J249) -> 2000.1 | O249: Skewness | P249: 2.6235831 | R249: Skewness | S249: -0.2142499
B250: 10704 | C250: 44922 | D250: Sides & Other | E250: Drive-thru | F250: Gift Card | G250: Walter Muller | H250: Berlin | I250: 4.99 | J250: 201 | K250: =PRODUCT(I250:J250) -> 1002.99 | O250: Range | P250: 21520.17 | R250: Range | S250: 554
B251: 10705 | C251: 44923 | D251: Burgers | E251: Drive-thru | F251: Gift Card | G251: Walter Muller | H251: Berlin | I251: 12.99 | J251: 724 | K251: =PRODUCT(I251:J251) -> 9404.76 | O251: Minimum | P251: 1002.99 | R251: Minimum | S251: 201
B252: 10706 | C252: 44923 | D252: Chicken Sandwiches | E252: Drive-thru | F252: Gift Card | G252: Walter Muller | H252: Berlin | I252: 9.95 | J252: 302 | K252: =PRODUCT(I252:J252) -> 3004.9 | O252: Maximum | P252: 22523.16 | R252: Maximum | S252: 755
B253: 10707 | C253: 44923 | D253: Fries | E253: Drive-thru | F253: Gift Card | G253: Walter Muller | H253: Berlin | I253: 3.49 | J253: 631 | K253: =PRODUCT(I253:J253) -> 2202.19 | O253: Sum | P253: 812135.13 | R253: Sum | S253: 118539
B254: 10708 | C254: 44923 | D254: Beverages | E254: Drive-thru | F254: Gift Card | G254: Walter Muller | H254: Berlin | I254: 2.95 | J254: 678 | K254: =PRODUCT(I254:J254) -> 2000.1 | O254: Count | P254: 257 | R254: Count | S254: 257
B255: 10709 | C255: 44923 | D255: Sides & Other | E255: Drive-thru | F255: Gift Card | G255: Walter Muller | H255: Berlin | I255: 4.99 | J255: 201 | K255: =PRODUCT(I255:J255) -> 1002.99
B256: 10710 | C256: 44924 | D256: Burgers | E256: Drive-thru | F256: Gift Card | G256: Walter Muller | H256: Berlin | I256: 12.99 | J256: 755 | K256: =PRODUCT(I256:J256) -> 9807.45
B257: 10711 | C257: 44924 | D257: Chicken Sandwiches | E257: Drive-thru | F257: Gift Card | G257: Walter Muller | H257: Berlin | I257: 9.95 | J257: 282 | K257: =PRODUCT(I257:J257) -> 2805.9
B258: 10712 | C258: 44924 | D258: Fries | E258: Drive-thru | F258: Gift Card | G258: Walter Muller | H258: Berlin | I258: 3.49 | J258: 631 | K258: =PRODUCT(I258:J258) -> 2202.19
B259: 10713 | C259: 44924 | D259: Beverages | E259: Drive-thru | F259: Gift Card | G259: Walter Muller | H259: Berlin | I259: 2.95 | J259: 678 | K259: =PRODUCT(I259:J259) -> 2000.1

Sheet Analysis
B2: Data Analysis Questions
I3: Row Labels | J3: Sum of Quantity
B4: 1) What is our best selling product? | I4: Beverages | J4: 35666 | K4: =I4 -> Beverages | L4: =J4 -> 35666
I5: Fries | J5: 32067 | K5: =I5 -> Fries | L5: =J5 -> 32067
B6: 2) What is our total revenue? | I6: Burgers | J6: 29572 | K6: =I6 -> Burgers | L6: =J6 -> 29572
I7: Chicken Sandwiches | J7: 11184 | K7: =I7 -> Chicken Sandwiches | L7: =J7 -> 11184
B8: 3) What is the revenue breakdown by payment method? | I8: Sides & Other | J8: 10050 | K8: =I8 -> Sides & Other | L8: =J8 -> 10050
I9: Grand Total | J9: 118539
B10: 4) what product gives more revenue?
I12: Sum of Total revenue
I13: 812135.13
I15: Row Labels | J15: Sum of Total revenue
I16: Cash | J16: 239494.15 | K16: =I16 -> Cash | L16: =J16 -> 239494.15
I17: Credit Card | J17: 403812.85 | K17: =I17 -> Credit Card | L17: =J17 -> 403812.85
I18: Gift Card | J18: 168828.13 | K18: =I18 -> Gift Card | L18: =J18 -> 168828.13
I19: Grand Total | J19: 812135.13
I21: Row Labels | J21: Sum of Total revenue
I22: Beverages | J22: 125737.76 | K22: =I22 -> Beverages | L22: =J22 -> 125737.76
I23: Burgers | J23: 392000.28 | K23: =I23 -> Burgers | L23: =J23 -> 392000.28
I24: Chicken Sandwiches | J24: 115139 | K24: =I24 -> Chicken Sandwiches | L24: =J24 -> 115139
I25: Fries | J25: 125802.14 | K25: =I25 -> Fries | L25: =J25 -> 125802.14
I26: Sides & Other | J26: 53455.95 | K26: =I26 -> Sides & Other | L26: =J26 -> 53455.95
I27: Grand Total | J27: 812135.13
I29: Row Labels | J29: Sum of Total revenue
I30: Berlin | J30: 100698.95 | K30: =Analysis!I30 -> Berlin | L30: =Analysis!J30 -> 100698.95
I31: Lisbon | J31: 283555.36 | K31: =Analysis!I31 -> Lisbon | L31: =Analysis!J31 -> 283555.36
I32: London | J32: 211522.88 | K32: =Analysis!I32 -> London | L32: =Analysis!J32 -> 211522.88
I33: Madrid | J33: 136430.04 | K33: =Analysis!I33 -> Madrid | L33: =Analysis!J33 -> 136430.04
I34: Paris | J34: 79927.9 | K34: =Analysis!I34 -> Paris | L34: =Analysis!J34 -> 79927.9
I35: Grand Total | J35: 812135.13
I37: Row Labels | J37: Sum of Total revenue
I38: Joao Silva | J38: 283555.36 | K38: =I38 -> Joao Silva | L38: =J38 -> 283555.36
I39: Pablo Perez | J39: 136430.04 | K39: =I39 -> Pablo Perez | L39: =J39 -> 136430.04
I40: Remy Monet | J40: 79927.9 | K40: =I40 -> Remy Monet | L40: =J40 -> 79927.9
I41: Tom Jackson | J41: 211522.88 | K41: =I41 -> Tom Jackson | L41: =J41 -> 211522.88
I42: Walter Muller | J42: 100698.95 | K42: =I42 -> Walter Muller | L42: =J42 -> 100698.95
I43: Grand Total | J43: 812135.13
I45: Row Labels | J45: Sum of Quantity
I46: Berlin | J46: 14785 | K46: =I46 -> Berlin | L46: =J46 -> 14785
I47: Lisbon | J47: 37196 | K47: =I47 -> Lisbon | L47: =J47 -> 37196
...

Sheet Charts
